<?xml version="1.0" ?>
<robot name="mpbot" xmlns:xacro="http://www.ros.org/wiki/xacro">

<xacro:include filename="$(find mpbot_description)/urdf/materials.xacro" />
<xacro:include filename="$(find mpbot_description)/urdf/mpbot.trans" />
<xacro:include filename="$(find mpbot_description)/gazebo/mpbot_materials.gazebo" />
<xacro:include filename="$(find mpbot_description)/gazebo/mpbot_physics.gazebo" />
<xacro:include filename="$(find mpbot_description)/gazebo/mpbot_plugins.gazebo" />

<link name="base_link">
  <inertial>
    <origin rpy="0 0 0" xyz="0.0999061760229392 0.07499417345841541 0.03494600887912029"/>
    <mass value="1.2782741906473842"/>
    <inertia ixx="0.002629" ixy="-0.0" ixz="-0.0" iyy="0.004417" iyz="0.0" izz="0.006709"/>
  </inertial>
  <visual>
    <origin rpy="0 0 0" xyz="0 0 0"/>
    <geometry>
      <mesh filename="package://mpbot_description/meshes/base_link.stl" scale="0.001 0.001 0.001"/>
    </geometry>
    <material name="silver"/>
  </visual>
  <collision>
    <origin rpy="0 0 0" xyz="0 0 0"/>
    <geometry>
      <mesh filename="package://mpbot_description/meshes/base_link.stl" scale="0.001 0.001 0.001"/>
    </geometry>
  </collision>
</link>

<link name="Wheel_1_1">
  <inertial>
    <origin rpy="0 0 0" xyz="-3.774758283725532e-14 0.005000000000000025 0.0"/>
    <mass value="0.052322243897833645"/>
    <inertia ixx="1.7e-05" ixy="0.0" ixz="-0.0" iyy="3.4e-05" iyz="-0.0" izz="1.7e-05"/>
  </inertial>
  <visual>
    <origin rpy="0 0 0" xyz="-0.15 0.015 -0.035"/>
    <geometry>
      <mesh filename="package://mpbot_description/meshes/Wheel_1_1.stl" scale="0.001 0.001 0.001"/>
    </geometry>
    <material name="silver"/>
  </visual>
  <collision>
    <origin rpy="0 0 0" xyz="-0.15 0.015 -0.035"/>
    <geometry>
      <mesh filename="package://mpbot_description/meshes/Wheel_1_1.stl" scale="0.001 0.001 0.001"/>
    </geometry>
  </collision>
</link>

<link name="Wheel_3_1">
  <inertial>
    <origin rpy="0 0 0" xyz="3.785166624581393e-14 0.005000000000000041 -1.3877787807814457e-17"/>
    <mass value="0.052322243897833645"/>
    <inertia ixx="1.7e-05" ixy="0.0" ixz="-0.0" iyy="3.4e-05" iyz="0.0" izz="1.7e-05"/>
  </inertial>
  <visual>
    <origin rpy="0 0 0" xyz="-0.05 0.015 -0.035"/>
    <geometry>
      <mesh filename="package://mpbot_description/meshes/Wheel_3_1.stl" scale="0.001 0.001 0.001"/>
    </geometry>
    <material name="silver"/>
  </visual>
  <collision>
    <origin rpy="0 0 0" xyz="-0.05 0.015 -0.035"/>
    <geometry>
      <mesh filename="package://mpbot_description/meshes/Wheel_3_1.stl" scale="0.001 0.001 0.001"/>
    </geometry>
  </collision>
</link>

<link name="Wheel_2_1">
  <inertial>
    <origin rpy="0 0 0" xyz="-3.7719827261639693e-14 -0.0050000000000000044 0.0"/>
    <mass value="0.052322243897833645"/>
    <inertia ixx="1.7e-05" ixy="-0.0" ixz="0.0" iyy="3.4e-05" iyz="0.0" izz="1.7e-05"/>
  </inertial>
  <visual>
    <origin rpy="0 0 0" xyz="-0.15 -0.165 -0.035"/>
    <geometry>
      <mesh filename="package://mpbot_description/meshes/Wheel_2_1.stl" scale="0.001 0.001 0.001"/>
    </geometry>
    <material name="silver"/>
  </visual>
  <collision>
    <origin rpy="0 0 0" xyz="-0.15 -0.165 -0.035"/>
    <geometry>
      <mesh filename="package://mpbot_description/meshes/Wheel_2_1.stl" scale="0.001 0.001 0.001"/>
    </geometry>
  </collision>
</link>

<link name="Wheel_4_1">
  <inertial>
    <origin rpy="0 0 0" xyz="3.770594947383188e-14 -0.0050000000000000044 0.0"/>
    <mass value="0.052322243897833645"/>
    <inertia ixx="1.7e-05" ixy="0.0" ixz="-0.0" iyy="3.4e-05" iyz="0.0" izz="1.7e-05"/>
  </inertial>
  <visual>
    <origin rpy="0 0 0" xyz="-0.05 -0.165 -0.035"/>
    <geometry>
      <mesh filename="package://mpbot_description/meshes/Wheel_4_1.stl" scale="0.001 0.001 0.001"/>
    </geometry>
    <material name="silver"/>
  </visual>
  <collision>
    <origin rpy="0 0 0" xyz="-0.05 -0.165 -0.035"/>
    <geometry>
      <mesh filename="package://mpbot_description/meshes/Wheel_4_1.stl" scale="0.001 0.001 0.001"/>
    </geometry>
  </collision>
</link>

<joint name="Rev1" type="continuous">
  <origin rpy="0 0 0" xyz="0.15 -0.015 0.035"/>
  <parent link="base_link"/>
  <child link="Wheel_1_1"/>
  <axis xyz="-0.0 1.0 0.0"/>
</joint>

<joint name="Rev2" type="continuous">
  <origin rpy="0 0 0" xyz="0.05 -0.015 0.035"/>
  <parent link="base_link"/>
  <child link="Wheel_3_1"/>
  <axis xyz="-0.0 1.0 0.0"/>
</joint>

<joint name="Rev3" type="continuous">
  <origin rpy="0 0 0" xyz="0.15 0.165 0.035"/>
  <parent link="base_link"/>
  <child link="Wheel_2_1"/>
  <axis xyz="0.0 1.0 -0.0"/>
</joint>

<joint name="Rev4" type="continuous">
  <origin rpy="0 0 0" xyz="0.05 0.165 0.035"/>
  <parent link="base_link"/>
  <child link="Wheel_4_1"/>
  <axis xyz="0.0 1.0 -0.0"/>
</joint>

</robot>
